<?xml version="1.0" ?>
<!-- =================================================================================== -->
<!-- |    This document was autogenerated by xacro from model.xacro                    | -->
<!-- |    EDITING THIS FILE BY HAND IS NOT RECOMMENDED                                 | -->
<!-- =================================================================================== -->
<robot xmlns:xacro="http://www.ros.org/wiki/xacro" name="robot">
  <material name="shell_color">
    <color rgba="1 1 1 1"/>
  </material>
  <material name="body_color">
    <color rgba="0.1 0.1 0.1 1"/>
  </material>
  <material name="foot_color">
    <color rgba="0 0.75 1 1"/>
  </material>
  <!-- Params -->
  <!-- Macros -->
  <!-- Macros joints -->
  <!-- Leg macros -->
  <!-- Robot Body -->
  <link name="base_link">
    <visual>
      <geometry>
        <mesh filename="package://stl/body.stl" scale="0.01 0.01 0.01"/>
      </geometry>
      <material name="body_color"/>
      <origin rpy="0 0 0" xyz="-0.286 -0.6 0.40"/>
    </visual>
    <collision>
      <geometry>
        <box size="0.6 1.4 0.25"/>
      </geometry>
      <origin rpy="0 0 0" xyz="0 0 0.6"/>
    </collision>
    <inertial>
      <mass value="2.80"/>
      <inertia ixx="100" ixy="0" ixz="0" iyy="100" iyz="0" izz="100"/>
    </inertial>
  </link>
  <link name="front_left_shoulder_link">
    <visual>
      <geometry>
        <mesh filename="package://stl/joint.stl" scale="0.01 0.01 0.01"/>
      </geometry>
      <origin rpy="0 0 3.14159" xyz="-0.12 -0.05 0.4"/>
      <material name="body_color"/>
    </visual>
    <collision>
      <geometry>
        <box size="0.044 0.038 0.25"/>
      </geometry>
      <origin rpy="0 0 0" xyz="0 0 0.6"/>
    </collision>
    <inertial>
      <mass value="0.10"/>
      <inertia ixx="100" ixy="0" ixz="0" iyy="100" iyz="0" izz="100"/>
    </inertial>
  </link>
  <link name="front_left_leg_link">
    <visual>
      <geometry>
        <mesh filename="package://stl/middle_joint.stl" scale="0.01 0.01 0.01"/>
      </geometry>
      <origin rpy="0 0 0" xyz="-1.7142 0 -0.011"/>
      <material name="body_color"/>
    </visual>
  </link>
  <link name="front_left_foot_link">
    <visual>
      <geometry>
        <mesh filename="package://stl/foot.stl" scale="0.01 0.01 0.01"/>
      </geometry>
      <origin rpy="0 3.14159 0" xyz="0.98 -0.485 0.0225"/>
      <material name="body_color"/>
    </visual>
    <collision>
      <geometry>
        <sphere radius="0.1"/>
      </geometry>
      <origin rpy="0 0 0" xyz="-0.8 0.98 0.0225"/>
      <contact_coefficients mu="1.1"/>
    </collision>
    <inertial>
      <mass value="0.1"/>
      <inertia ixx="1000" ixy="0" ixz="0" iyy="1000" iyz="0" izz="1000"/>
    </inertial>
  </link>
  <joint name="front_left_shoulder" type="revolute">
    <parent link="base_link"/>
    <child link="front_left_shoulder_link"/>
    <axis xyz="0 0 1"/>
    <origin rpy="0 0 2.35619" xyz="0.37 -0.69 0"/>
    <limit effort="1000.0" lower="-0.548" upper="0.548" velocity="0.7"/>
    <dynamics damping="0.0" friction="0.5"/>
  </joint>
  <joint name="front_left_leg" type="revolute">
    <parent link="front_left_shoulder_link"/>
    <child link="front_left_leg_link"/>
    <axis xyz="0 1 0"/>
    <origin rpy="0 0 0" xyz="-0.28 -1.015 0.59"/>
    <limit effort="1000.0" lower="-2.666" upper="1.548" velocity="0.5"/>
    <dynamics damping="0.0" friction="0.0"/>
  </joint>
  <joint name="front_left_foot" type="revolute">
    <parent link="front_left_leg_link"/>
    <child link="front_left_foot_link"/>
    <axis xyz="0 1 0"/>
    <origin rpy="0 0 0" xyz="-0.43 0 -0"/>
    <limit effort="1000.0" lower="-2.6" upper="0.1" velocity="0.5"/>
    <dynamics damping="0.0" friction="0.5"/>
  </joint>
  <link name="front_right_shoulder_link">
    <visual>
      <geometry>
        <mesh filename="package://stl/joint.stl" scale="0.01 0.01 0.01"/>
      </geometry>
      <origin rpy="0 0 3.14159" xyz="-0.12 -0.05 0.4"/>
      <material name="body_color"/>
    </visual>
    <collision>
      <geometry>
        <box size="0.044 0.038 0.25"/>
      </geometry>
      <origin rpy="0 0 0" xyz="0 0 0.6"/>
    </collision>
    <inertial>
      <mass value="0.10"/>
      <inertia ixx="100" ixy="0" ixz="0" iyy="100" iyz="0" izz="100"/>
    </inertial>
  </link>
  <link name="front_right_leg_link">
    <visual>
      <geometry>
        <mesh filename="package://stl/middle_joint.stl" scale="0.01 0.01 0.01"/>
      </geometry>
      <origin rpy="0 0 0" xyz="-1.7142 0 -0.011"/>
      <material name="body_color"/>
    </visual>
  </link>
  <link name="front_right_foot_link">
    <visual>
      <geometry>
        <mesh filename="package://stl/foot.stl" scale="0.01 0.01 0.01"/>
      </geometry>
      <origin rpy="0 3.14159 0" xyz="0.98 -0.485 0.0225"/>
      <material name="body_color"/>
    </visual>
    <collision>
      <geometry>
        <sphere radius="0.1"/>
      </geometry>
      <origin rpy="0 0 0" xyz="-0.8 0.98 0.0225"/>
      <contact_coefficients mu="1.1"/>
    </collision>
    <inertial>
      <mass value="0.1"/>
      <inertia ixx="1000" ixy="0" ixz="0" iyy="1000" iyz="0" izz="1000"/>
    </inertial>
  </link>
  <joint name="front_right_shoulder" type="revolute">
    <parent link="base_link"/>
    <child link="front_right_shoulder_link"/>
    <axis xyz="0 0 1"/>
    <origin rpy="0 0 0.785398" xyz="-0.37 -0.69 0"/>
    <limit effort="1000.0" lower="-0.548" upper="0.548" velocity="0.7"/>
    <dynamics damping="0.0" friction="0.5"/>
  </joint>
  <joint name="front_right_leg" type="revolute">
    <parent link="front_right_shoulder_link"/>
    <child link="front_right_leg_link"/>
    <axis xyz="0 1 0"/>
    <origin rpy="0 0 0" xyz="-0.28 -1.015 0.59"/>
    <limit effort="1000.0" lower="-2.666" upper="1.548" velocity="0.5"/>
    <dynamics damping="0.0" friction="0.0"/>
  </joint>
  <joint name="front_right_foot" type="revolute">
    <parent link="front_right_leg_link"/>
    <child link="front_right_foot_link"/>
    <axis xyz="0 1 0"/>
    <origin rpy="0 0 0" xyz="-0.43 0 -0"/>
    <limit effort="1000.0" lower="-2.6" upper="0.1" velocity="0.5"/>
    <dynamics damping="0.0" friction="0.5"/>
  </joint>
  <link name="middle_left_shoulder_link">
    <visual>
      <geometry>
        <mesh filename="package://stl/joint.stl" scale="0.01 0.01 0.01"/>
      </geometry>
      <origin rpy="0 0 3.14159" xyz="-0.12 -0.05 0.4"/>
      <material name="body_color"/>
    </visual>
    <collision>
      <geometry>
        <box size="0.044 0.038 0.25"/>
      </geometry>
      <origin rpy="0 0 0" xyz="0 0 0.6"/>
    </collision>
    <inertial>
      <mass value="0.10"/>
      <inertia ixx="100" ixy="0" ixz="0" iyy="100" iyz="0" izz="100"/>
    </inertial>
  </link>
  <link name="middle_left_leg_link">
    <visual>
      <geometry>
        <mesh filename="package://stl/middle_joint.stl" scale="0.01 0.01 0.01"/>
      </geometry>
      <origin rpy="0 0 0" xyz="-1.7142 0 -0.011"/>
      <material name="body_color"/>
    </visual>
  </link>
  <link name="middle_left_foot_link">
    <visual>
      <geometry>
        <mesh filename="package://stl/foot.stl" scale="0.01 0.01 0.01"/>
      </geometry>
      <origin rpy="0 3.14159 0" xyz="0.98 -0.485 0.0225"/>
      <material name="body_color"/>
    </visual>
    <collision>
      <geometry>
        <sphere radius="0.1"/>
      </geometry>
      <origin rpy="0 0 0" xyz="-0.8 0.98 0.0225"/>
      <contact_coefficients mu="1.1"/>
    </collision>
    <inertial>
      <mass value="0.1"/>
      <inertia ixx="1000" ixy="0" ixz="0" iyy="1000" iyz="0" izz="1000"/>
    </inertial>
  </link>
  <joint name="middle_left_shoulder" type="revolute">
    <parent link="base_link"/>
    <child link="middle_left_shoulder_link"/>
    <axis xyz="0 0 1"/>
    <origin rpy="0 0 3.14159" xyz="0.51 0 0"/>
    <limit effort="1000.0" lower="-0.548" upper="0.548" velocity="0.7"/>
    <dynamics damping="0.0" friction="0.5"/>
  </joint>
  <joint name="middle_left_leg" type="revolute">
    <parent link="middle_left_shoulder_link"/>
    <child link="middle_left_leg_link"/>
    <axis xyz="0 1 0"/>
    <origin rpy="0 0 0" xyz="-0.28 -1.015 0.59"/>
    <limit effort="1000.0" lower="-2.666" upper="1.548" velocity="0.5"/>
    <dynamics damping="0.0" friction="0.0"/>
  </joint>
  <joint name="middle_left_foot" type="revolute">
    <parent link="middle_left_leg_link"/>
    <child link="middle_left_foot_link"/>
    <axis xyz="0 1 0"/>
    <origin rpy="0 0 0" xyz="-0.43 0 -0"/>
    <limit effort="1000.0" lower="-2.6" upper="0.1" velocity="0.5"/>
    <dynamics damping="0.0" friction="0.5"/>
  </joint>
  <link name="middle_right_shoulder_link">
    <visual>
      <geometry>
        <mesh filename="package://stl/joint.stl" scale="0.01 0.01 0.01"/>
      </geometry>
      <origin rpy="0 0 3.14159" xyz="-0.12 -0.05 0.4"/>
      <material name="body_color"/>
    </visual>
    <collision>
      <geometry>
        <box size="0.044 0.038 0.25"/>
      </geometry>
      <origin rpy="0 0 0" xyz="0 0 0.6"/>
    </collision>
    <inertial>
      <mass value="0.10"/>
      <inertia ixx="100" ixy="0" ixz="0" iyy="100" iyz="0" izz="100"/>
    </inertial>
  </link>
  <link name="middle_right_leg_link">
    <visual>
      <geometry>
        <mesh filename="package://stl/middle_joint.stl" scale="0.01 0.01 0.01"/>
      </geometry>
      <origin rpy="0 0 0" xyz="-1.7142 0 -0.011"/>
      <material name="body_color"/>
    </visual>
  </link>
  <link name="middle_right_foot_link">
    <visual>
      <geometry>
        <mesh filename="package://stl/foot.stl" scale="0.01 0.01 0.01"/>
      </geometry>
      <origin rpy="0 3.14159 0" xyz="0.98 -0.485 0.0225"/>
      <material name="body_color"/>
    </visual>
    <collision>
      <geometry>
        <sphere radius="0.1"/>
      </geometry>
      <origin rpy="0 0 0" xyz="-0.8 0.98 0.0225"/>
      <contact_coefficients mu="1.1"/>
    </collision>
    <inertial>
      <mass value="0.1"/>
      <inertia ixx="1000" ixy="0" ixz="0" iyy="1000" iyz="0" izz="1000"/>
    </inertial>
  </link>
  <joint name="middle_right_shoulder" type="revolute">
    <parent link="base_link"/>
    <child link="middle_right_shoulder_link"/>
    <axis xyz="0 0 1"/>
    <origin rpy="0 0 0" xyz="-0.51 0 0"/>
    <limit effort="1000.0" lower="-0.548" upper="0.548" velocity="0.7"/>
    <dynamics damping="0.0" friction="0.5"/>
  </joint>
  <joint name="middle_right_leg" type="revolute">
    <parent link="middle_right_shoulder_link"/>
    <child link="middle_right_leg_link"/>
    <axis xyz="0 1 0"/>
    <origin rpy="0 0 0" xyz="-0.28 -1.015 0.59"/>
    <limit effort="1000.0" lower="-2.666" upper="1.548" velocity="0.5"/>
    <dynamics damping="0.0" friction="0.0"/>
  </joint>
  <joint name="middle_right_foot" type="revolute">
    <parent link="middle_right_leg_link"/>
    <child link="middle_right_foot_link"/>
    <axis xyz="0 1 0"/>
    <origin rpy="0 0 0" xyz="-0.43 0 -0"/>
    <limit effort="1000.0" lower="-2.6" upper="0.1" velocity="0.5"/>
    <dynamics damping="0.0" friction="0.5"/>
  </joint>
  <link name="back_left_shoulder_link">
    <visual>
      <geometry>
        <mesh filename="package://stl/joint.stl" scale="0.01 0.01 0.01"/>
      </geometry>
      <origin rpy="0 0 3.14159" xyz="-0.12 -0.05 0.4"/>
      <material name="body_color"/>
    </visual>
    <collision>
      <geometry>
        <box size="0.044 0.038 0.25"/>
      </geometry>
      <origin rpy="0 0 0" xyz="0 0 0.6"/>
    </collision>
    <inertial>
      <mass value="0.10"/>
      <inertia ixx="100" ixy="0" ixz="0" iyy="100" iyz="0" izz="100"/>
    </inertial>
  </link>
  <link name="back_left_leg_link">
    <visual>
      <geometry>
        <mesh filename="package://stl/middle_joint.stl" scale="0.01 0.01 0.01"/>
      </geometry>
      <origin rpy="0 0 0" xyz="-1.7142 0 -0.011"/>
      <material name="body_color"/>
    </visual>
  </link>
  <link name="back_left_foot_link">
    <visual>
      <geometry>
        <mesh filename="package://stl/foot.stl" scale="0.01 0.01 0.01"/>
      </geometry>
      <origin rpy="0 3.14159 0" xyz="0.98 -0.485 0.0225"/>
      <material name="body_color"/>
    </visual>
    <collision>
      <geometry>
        <sphere radius="0.1"/>
      </geometry>
      <origin rpy="0 0 0" xyz="-0.8 0.98 0.0225"/>
      <contact_coefficients mu="1.1"/>
    </collision>
    <inertial>
      <mass value="0.1"/>
      <inertia ixx="1000" ixy="0" ixz="0" iyy="1000" iyz="0" izz="1000"/>
    </inertial>
  </link>
  <joint name="back_left_shoulder" type="revolute">
    <parent link="base_link"/>
    <child link="back_left_shoulder_link"/>
    <axis xyz="0 0 1"/>
    <origin rpy="0 0 -2.35619" xyz="0.37 0.69 0"/>
    <limit effort="1000.0" lower="-0.548" upper="0.548" velocity="0.7"/>
    <dynamics damping="0.0" friction="0.5"/>
  </joint>
  <joint name="back_left_leg" type="revolute">
    <parent link="back_left_shoulder_link"/>
    <child link="back_left_leg_link"/>
    <axis xyz="0 1 0"/>
    <origin rpy="0 0 0" xyz="-0.28 -1.015 0.59"/>
    <limit effort="1000.0" lower="-2.666" upper="1.548" velocity="0.5"/>
    <dynamics damping="0.0" friction="0.0"/>
  </joint>
  <joint name="back_left_foot" type="revolute">
    <parent link="back_left_leg_link"/>
    <child link="back_left_foot_link"/>
    <axis xyz="0 1 0"/>
    <origin rpy="0 0 0" xyz="-0.43 0 -0"/>
    <limit effort="1000.0" lower="-2.6" upper="0.1" velocity="0.5"/>
    <dynamics damping="0.0" friction="0.5"/>
  </joint>
  <link name="back_right_shoulder_link">
    <visual>
      <geometry>
        <mesh filename="package://stl/joint.stl" scale="0.01 0.01 0.01"/>
      </geometry>
      <origin rpy="0 0 3.14159" xyz="-0.12 -0.05 0.4"/>
      <material name="body_color"/>
    </visual>
    <collision>
      <geometry>
        <box size="0.044 0.038 0.25"/>
      </geometry>
      <origin rpy="0 0 0" xyz="0 0 0.6"/>
    </collision>
    <inertial>
      <mass value="0.10"/>
      <inertia ixx="100" ixy="0" ixz="0" iyy="100" iyz="0" izz="100"/>
    </inertial>
  </link>
  <link name="back_right_leg_link">
    <visual>
      <geometry>
        <mesh filename="package://stl/middle_joint.stl" scale="0.01 0.01 0.01"/>
      </geometry>
      <origin rpy="0 0 0" xyz="-1.7142 0 -0.011"/>
      <material name="body_color"/>
    </visual>
  </link>
  <link name="back_right_foot_link">
    <visual>
      <geometry>
        <mesh filename="package://stl/foot.stl" scale="0.01 0.01 0.01"/>
      </geometry>
      <origin rpy="0 3.14159 0" xyz="0.98 -0.485 0.0225"/>
      <material name="body_color"/>
    </visual>
    <collision>
      <geometry>
        <sphere radius="0.1"/>
      </geometry>
      <origin rpy="0 0 0" xyz="-0.8 0.98 0.0225"/>
      <contact_coefficients mu="1.1"/>
    </collision>
    <inertial>
      <mass value="0.1"/>
      <inertia ixx="1000" ixy="0" ixz="0" iyy="1000" iyz="0" izz="1000"/>
    </inertial>
  </link>
  <joint name="back_right_shoulder" type="revolute">
    <parent link="base_link"/>
    <child link="back_right_shoulder_link"/>
    <axis xyz="0 0 1"/>
    <origin rpy="0 0 -0.785398" xyz="-0.37 0.69 0"/>
    <limit effort="1000.0" lower="-0.548" upper="0.548" velocity="0.7"/>
    <dynamics damping="0.0" friction="0.5"/>
  </joint>
  <joint name="back_right_leg" type="revolute">
    <parent link="back_right_shoulder_link"/>
    <child link="back_right_leg_link"/>
    <axis xyz="0 1 0"/>
    <origin rpy="0 0 0" xyz="-0.28 -1.015 0.59"/>
    <limit effort="1000.0" lower="-2.666" upper="1.548" velocity="0.5"/>
    <dynamics damping="0.0" friction="0.0"/>
  </joint>
  <joint name="back_right_foot" type="revolute">
    <parent link="back_right_leg_link"/>
    <child link="back_right_foot_link"/>
    <axis xyz="0 1 0"/>
    <origin rpy="0 0 0" xyz="-0.43 0 -0"/>
    <limit effort="1000.0" lower="-2.6" upper="0.1" velocity="0.5"/>
    <dynamics damping="0.0" friction="0.5"/>
  </joint>
</robot>
